Workbook

Sheet Panel
B2: UNIVERSIDAD DE CUNDINAMARCA · CADI · MEDIT
B3: Cronograma de producción de 200 PAD
B4: 16 de septiembre a 30 de noviembre de 2026 · Planes de Aprendizaje Digital
B6: INDICADORES DEL PERIODO
B7: Indicador | C7: Valor | D7: Unidad
B8: Meta total del periodo | C8: =Parámetros!C6 -> 200 | D8: PAD
B9: PAD por ingeniero | C9: =Parámetros!C6/Parámetros!C7 -> 100 | D9: PAD
B10: Días L–V del periodo | C10: =Parámetros!C9 -> 54 | D10: días
B11: Festivos de ley excluidos | C11: =Parámetros!C9-Parámetros!C10 -> 3 | D11: días
B12: Días hábiles efectivos | C12: =Parámetros!C10 -> 51 | D12: días
B13: Carga media programada | C13: =ROUND(Parámetros!C6/Parámetros!C10,2) -> 3.92 | D13: PAD/día
B14: Pico de carga diaria | C14: =MAX(Calendario!I2:I55) -> 34 | D14: PAD/día
B15: PAD virtualizados (real) | C15: =SUM('Bitácora diaria'!H:H) -> 126 | D15: PAD
B16: Avance sobre la meta | C16: =IFERROR(SUM('Bitácora diaria'!H:H)/Parámetros!C6,0) -> 0.63 | D16: %
B18: META POR QUINCENA E INGENIERO
B19: Quincena | C19: Periodo | D19: Días hábiles | E19: Juan Manuel | F19: Juan Pablo | G19: Total quincena | H19: Acumulado
B20: Q1 | C20: 16 Sep – 15 Oct | D20: 21 | E20: =SUMIFS(Lotes!G:G,Lotes!B:B,$B20,Lotes!D:D,"Juan Manuel") -> 25 | F20: =SUMIFS(Lotes!G:G,Lotes!B:B,$B20,Lotes!D:D,"Juan Pablo") -> 25 | G20: =SUM(E20:F20) -> 50 | H20: =SUM($G$20:G20) -> 50
B21: Q2 | C21: 16 – 30 Oct | D21: 11 | E21: =SUMIFS(Lotes!G:G,Lotes!B:B,$B21,Lotes!D:D,"Juan Manuel") -> 25 | F21: =SUMIFS(Lotes!G:G,Lotes!B:B,$B21,Lotes!D:D,"Juan Pablo") -> 25 | G21: =SUM(E21:F21) -> 50 | H21: =SUM($G$20:G21) -> 100
B22: Q3 | C22: 1 – 15 Nov | D22: 9 | E22: =SUMIFS(Lotes!G:G,Lotes!B:B,$B22,Lotes!D:D,"Juan Manuel") -> 25 | F22: =SUMIFS(Lotes!G:G,Lotes!B:B,$B22,Lotes!D:D,"Juan Pablo") -> 25 | G22: =SUM(E22:F22) -> 50 | H22: =SUM($G$20:G22) -> 150
B23: Q4 | C23: 16 – 30 Nov | D23: 10 | E23: =SUMIFS(Lotes!G:G,Lotes!B:B,$B23,Lotes!D:D,"Juan Manuel") -> 25 | F23: =SUMIFS(Lotes!G:G,Lotes!B:B,$B23,Lotes!D:D,"Juan Pablo") -> 25 | G23: =SUM(E23:F23) -> 50 | H23: =SUM($G$20:G23) -> 200
B24: TOTAL | D24: =SUM(D20:D23) -> 51 | E24: =SUM(E20:E23) -> 100 | F24: =SUM(F20:F23) -> 100 | G24: =SUM(G20:G23) -> 200
B27: PAD-DÍA PROGRAMADOS POR FASE
B28: Fase MCA | C28: Juan Manuel | D28: Juan Pablo | E28: Total
B29: Generación | C29: =SUMIFS('Bitácora diaria'!G:G,'Bitácora diaria'!F:F,$B29,'Bitácora diaria'!D:D,"Juan Manuel") -> 100 | D29: =SUMIFS('Bitácora diaria'!G:G,'Bitácora diaria'!F:F,$B29,'Bitácora diaria'!D:D,"Juan Pablo") -> 100 | E29: =SUM(C29:D29) -> 200
B30: Revisión | C30: =SUMIFS('Bitácora diaria'!G:G,'Bitácora diaria'!F:F,$B30,'Bitácora diaria'!D:D,"Juan Manuel") -> 100 | D30: =SUMIFS('Bitácora diaria'!G:G,'Bitácora diaria'!F:F,$B30,'Bitácora diaria'!D:D,"Juan Pablo") -> 100 | E30: =SUM(C30:D30) -> 200
B31: Control de calidad | C31: =SUMIFS('Bitácora diaria'!G:G,'Bitácora diaria'!F:F,$B31,'Bitácora diaria'!D:D,"Juan Manuel") -> 100 | D31: =SUMIFS('Bitácora diaria'!G:G,'Bitácora diaria'!F:F,$B31,'Bitácora diaria'!D:D,"Juan Pablo") -> 100 | E31: =SUM(C31:D31) -> 200
B32: Virtualización | C32: =SUMIFS('Bitácora diaria'!G:G,'Bitácora diaria'!F:F,$B32,'Bitácora diaria'!D:D,"Juan Manuel") -> 100 | D32: =SUMIFS('Bitácora diaria'!G:G,'Bitácora diaria'!F:F,$B32,'Bitácora diaria'!D:D,"Juan Pablo") -> 100 | E32: =SUM(C32:D32) -> 200
B35: Leyenda: las celdas con fondo amarillo de la hoja «Bitácora diaria» (columna Real) son las únicas que se diligencian a mano. Todo lo demás se calcula.

Sheet Parámetros
B2: Parámetros y supuestos operativos
B3: Parámetro | C3: Valor | D3: Fuente / nota
B4: Fecha de inicio | C4: 46281 | D4: Acta de planeación CADI
B5: Fecha de cierre | C5: 46356 | D5: Meta institucional
B6: Meta total de PAD | C6: 200 | D6: Definida en tablero de planeación
B7: Ingenieros asignados | C7: 2 | D7: Juan Manuel (mañana) y Juan Pablo (tarde)
B8: Jornada | C8: Lunes a viernes | D8: Mañana y tarde por ingeniero
B9: Días L–V del periodo | C9: 54 | D9: Conteo calendario
B10: Días hábiles efectivos | C10: 51 | D10: 54 días L–V menos 3 festivos de ley
B11: Fases del ciclo PAD | C11: 4 | D11: Generación · Revisión · Control de calidad · Virtualización
B12: Traslape entre fases | C12: 1 | D12: días — la fase siguiente inicia el último día de la anterior
B14: Festivos excluidos (Ley 51 de 1983)
B15: Fecha | C15: Día | D15: Celebración
B16: 46307 | C16: Lunes | D16: Día de la Raza
B17: 46328 | C17: Lunes | D17: Todos los Santos
B18: 46342 | C18: Lunes | D18: Independencia de Cartagena
B21: Reglas de cálculo
B22: · Cada ingeniero entrega 25 PAD por quincena: 100 PAD por ingeniero, 200 en total al 30 de noviembre.
B23: · Cada lote de 25 PAD recorre las cuatro fases dentro de su quincena, con un día de traslape entre fase y fase.
B24: · Los 25 PAD de una fase se reparten de forma pareja entre los días hábiles de su ventana; el residuo se asigna a los primeros días, de modo que la suma por fase siempre cierra en 25.
B25: · Supuesto operativo: Q1 abarca del 16 de septiembre al 15 de octubre (21 días hábiles) por ser el bloque de arranque. Q2, Q3 y Q4 son quincenas calendario de 9 a 11 días hábiles, por lo que la carga diaria sube en el tramo final.
B26: · La columna Real de la bitácora se diligencia manualmente; el resto del libro se recalcula solo.

Sheet Bitácora diaria
A1: Fecha | B1: Día | C1: Semana | D1: Ingeniero | E1: Quincena | F1: Fase | G1: Plan | H1: Real | I1: Δ | J1: Observación
A2: 46281 | B2: Miércoles | C2: 38 | D2: Juan Manuel | E2: Q1 | F2: Generación | G2: 4 | H2: 0 | I2: =IF(H2="","",H2-G2) -> -4 | J2: Ejemplo de diligenciamiento: escriba en «Real» los PAD efectivamente entregados ese día.
A3: 46281 | B3: Miércoles | C3: 38 | D3: Juan Pablo | E3: Q1 | F3: Generación | G3: 4 | H3: 0 | I3: =IF(H3="","",H3-G3) -> -4
A4: 46282 | B4: Jueves | C4: 38 | D4: Juan Manuel | E4: Q1 | F4: Generación | G4: 4 | H4: 0 | I4: =IF(H4="","",H4-G4) -> -4
A5: 46282 | B5: Jueves | C5: 38 | D5: Juan Pablo | E5: Q1 | F5: Generación | G5: 4 | H5: 0 | I5: =IF(H5="","",H5-G5) -> -4
A6: 46283 | B6: Viernes | C6: 38 | D6: Juan Manuel | E6: Q1 | F6: Generación | G6: 4 | H6: 0 | I6: =IF(H6="","",H6-G6) -> -4
A7: 46283 | B7: Viernes | C7: 38 | D7: Juan Pablo | E7: Q1 | F7: Generación | G7: 4 | H7: 0 | I7: =IF(H7="","",H7-G7) -> -4
A8: 46286 | B8: Lunes | C8: 39 | D8: Juan Manuel | E8: Q1 | F8: Generación | G8: 4 | H8: 0 | I8: =IF(H8="","",H8-G8) -> -4
A9: 46286 | B9: Lunes | C9: 39 | D9: Juan Pablo | E9: Q1 | F9: Generación | G9: 4 | H9: 0 | I9: =IF(H9="","",H9-G9) -> -4
A10: 46287 | B10: Martes | C10: 39 | D10: Juan Manuel | E10: Q1 | F10: Generación | G10: 3 | H10: 0 | I10: =IF(H10="","",H10-G10) -> -3
A11: 46287 | B11: Martes | C11: 39 | D11: Juan Pablo | E11: Q1 | F11: Generación | G11: 3 | H11: 0 | I11: =IF(H11="","",H11-G11) -> -3
A12: 46288 | B12: Miércoles | C12: 39 | D12: Juan Manuel | E12: Q1 | F12: Generación | G12: 3 | H12: 0 | I12: =IF(H12="","",H12-G12) -> -3
A13: 46288 | B13: Miércoles | C13: 39 | D13: Juan Pablo | E13: Q1 | F13: Generación | G13: 3 | H13: 0 | I13: =IF(H13="","",H13-G13) -> -3
A14: 46289 | B14: Jueves | C14: 39 | D14: Juan Manuel | E14: Q1 | F14: Generación | G14: 3 | H14: 0 | I14: =IF(H14="","",H14-G14) -> -3
... A41: 46303 | B41: Jueves | C41: 41 | D41: Juan Pablo | E41: Q1 | F41: Virtualización | G41: 5 | H41: 0 | I41: =IF(H41="","",H41-G41) -> -5
A42: 46304 | B42: Viernes | C42: 41 | D42: Juan Manuel | E42: Q1 | F42: Virtualización | G42: 5 | I42: =IF(H42="","",H42-G42)
A43: 46304 | B43: Viernes | C43: 41 | D43: Juan Pablo | E43: Q1 | F43: Virtualización | G43: 5 | I43: =IF(H43="","",H43-G43)
A44: 46308 | B44: Martes | C44: 42 | D44: Juan Manuel | E44: Q1 | F44: Virtualización | G44: 5 | I44: =IF(H44="","",H44-G44)
A45: 46308 | B45: Martes | C45: 42 | D45: Juan Pablo | E45: Q1 | F45: Virtualización | G45: 5 | I45: =IF(H45="","",H45-G45)
A46: 46309 | B46: Miércoles | C46: 42 | D46: Juan Manuel | E46: Q1 | F46: Virtualización | G46: 5 | I46: =IF(H46="","",H46-G46)
A47: 46309 | B47: Miércoles | C47: 42 | D47: Juan Pablo | E47: Q1 | F47: Virtualización | G47: 5 | I47: =IF(H47="","",H47-G47)
A48: 46310 | B48: Jueves | C48: 42 | D48: Juan Manuel | E48: Q1 | F48: Virtualización | G48: 5 | I48: =IF(H48="","",H48-G48)
A49: 46310 | B49: Jueves | C49: 42 | D49: Juan Pablo | E49: Q1 | F49: Virtualización | G49: 5 | I49: =IF(H49="","",H49-G49)
A50: 46311 | B50: Viernes | C50: 42 | D50: Juan Manuel | E50: Q2 | F50: Generación | G50: 7 | I50: =IF(H50="","",H50-G50)
A51: 46311 | B51: Viernes | C51: 42 | D51: Juan Pablo | E51: Q2 | F51: Generación | G51: 7 | I51: =IF(H51="","",H51-G51)
A52: 46314 | B52: Lunes | C52: 43 | D52: Juan Manuel | E52: Q2 | F52: Generación | G52: 6 | I52: =IF(H52="","",H52-G52)
A53: 46314 | B53: Lunes | C53: 43 | D53: Juan Pablo | E53: Q2 | F53: Generación | G53: 6 | I53: =IF(H53="","",H53-G53)
... A127: 46356 | B127: Lunes | C127: 49 | D127: Juan Pablo | E127: Q4 | F127: Virtualización | G127: 8 | I127: =IF(H127="","",H127-G127)
F129: TOTAL | G129: =SUM(G2:G127) -> 800 | H129: =SUM(H2:H127) -> 63 | I129: =IF(H129=0,"",H129-G129) -> -737

Sheet Lotes
B2: Lotes por quincena e ingeniero
B3: Quincena | C3: Periodo | D3: Ingeniero | E3: Jornada | F3: Rango de PAD | G3: Meta | H3: Inicio | I3: Cierre | J3: Días hábiles
B4: Q1 | C4: 16 Sep – 15 Oct | D4: Juan Manuel | E4: Jornada mañana | F4: PAD-001 a PAD-025 | G4: 25 | H4: 46281 | I4: 46310 | J4: 21
B5: Q1 | C5: 16 Sep – 15 Oct | D5: Juan Pablo | E5: Jornada tarde | F5: PAD-101 a PAD-125 | G5: 25 | H5: 46281 | I5: 46310 | J5: 21
B6: Q2 | C6: 16 – 30 Oct | D6: Juan Manuel | E6: Jornada mañana | F6: PAD-026 a PAD-050 | G6: 25 | H6: 46311 | I6: 46325 | J6: 11
B7: Q2 | C7: 16 – 30 Oct | D7: Juan Pablo | E7: Jornada tarde | F7: PAD-126 a PAD-150 | G7: 25 | H7: 46311 | I7: 46325 | J7: 11
B8: Q3 | C8: 1 – 15 Nov | D8: Juan Manuel | E8: Jornada mañana | F8: PAD-051 a PAD-075 | G8: 25 | H8: 46327 | I8: 46341 | J8: 9
B9: Q3 | C9: 1 – 15 Nov | D9: Juan Pablo | E9: Jornada tarde | F9: PAD-151 a PAD-175 | G9: 25 | H9: 46327 | I9: 46341 | J9: 9
B10: Q4 | C10: 16 – 30 Nov | D10: Juan Manuel | E10: Jornada mañana | F10: PAD-076 a PAD-100 | G10: 25 | H10: 46342 | I10: 46356 | J10: 10
B11: Q4 | C11: 16 – 30 Nov | D11: Juan Pablo | E11: Jornada tarde | F11: PAD-176 a PAD-200 | G11: 25 | H11: 46342 | I11: 46356 | J11: 10
B12: TOTAL | G12: =SUM(G4:G11) -> 200

Sheet Calendario
A1: Fecha | B1: Día | C1: Hábil | D1: Gen. | E1: Rev. | F1: C. calidad | G1: Virtual. | H1: Total del día | I1: Total día
A2: 46281 | B2: Miércoles | C2: Hábil | D2: =SUMIFS('Bitácora diaria'!$G:$G,'Bitácora diaria'!$A:$A,$A2,'Bitácora diaria'!$F:$F,"Generación") -> 8 | E2: =SUMIFS('Bitácora diaria'!$G:$G,'Bitácora diaria'!$A:$A,$A2,'Bitácora diaria'!$F:$F,"Revisión") -> 0 | F2: =SUMIFS('Bitácora diaria'!$G:$G,'Bitácora diaria'!$A:$A,$A2,'Bitácora diaria'!$F:$F,"Control de calidad") -> 0 | G2: =SUMIFS('Bitácora diaria'!$G:$G,'Bitácora diaria'!$A:$A,$A2,'Bitácora diaria'!$F:$F,"Virtualización") -> 0 | I2: =SUM(D2:G2) -> 8
A3: 46282 | B3: Jueves | C3: Hábil | D3: =SUMIFS('Bitácora diaria'!$G:$G,'Bitácora diaria'!$A:$A,$A3,'Bitácora diaria'!$F:$F,"Generación") -> 8 | E3: =SUMIFS('Bitácora diaria'!$G:$G,'Bitácora diaria'!$A:$A,$A3,'Bitácora diaria'!$F:$F,"Revisión") -> 0 | F3: =SUMIFS('Bitácora diaria'!$G:$G,'Bitácora diaria'!$A:$A,$A3,'Bitácora diaria'!$F:$F,"Control de calidad") -> 0 | G3: =SUMIFS('Bitácora diaria'!$G:$G,'Bitácora diaria'!$A:$A,$A3,'Bitácora diaria'!$F:$F,"Virtualización") -> 0 | I3: =SUM(D3:G3) -> 8
A4: 46283 | B4: Viernes | C4: Hábil | D4: =SUMIFS('Bitácora diaria'!$G:$G,'Bitácora diaria'!$A:$A,$A4,'Bitácora diaria'!$F:$F,"Generación") -> 8 | E4: =SUMIFS('Bitácora diaria'!$G:$G,'Bitácora diaria'!$A:$A,$A4,'Bitácora diaria'!$F:$F,"Revisión") -> 0 | F4: =SUMIFS('Bitácora diaria'!$G:$G,'Bitácora diaria'!$A:$A,$A4,'Bitácora diaria'!$F:$F,"Control de calidad") -> 0 | G4: =SUMIFS('Bitácora diaria'!$G:$G,'Bitácora diaria'!$A:$A,$A4,'Bitácora diaria'!$F:$F,"Virtualización") -> 0 | I4: =SUM(D4:G4) -> 8
A5: 46286 | B5: Lunes | C5: Hábil | D5: =SUMIFS('Bitácora diaria'!$G:$G,'Bitácora diaria'!$A:$A,$A5,'Bitácora diaria'!$F:$F,"Generación") -> 8 | E5: =SUMIFS('Bitácora diaria'!$G:$G,'Bitácora diaria'!$A:$A,$A5,'Bitácora diaria'!$F:$F,"Revisión") -> 0 | F5: =SUMIFS('Bitácora diaria'!$G:$G,'Bitácora diaria'!$A:$A,$A5,'Bitácora diaria'!$F:$F,"Control de calidad") -> 0 | G5: =SUMIFS('Bitácora diaria'!$G:$G,'Bitácora diaria'!$A:$A,$A5,'Bitácora diaria'!$F:$F,"Virtualización") -> 0 | I5: =SUM(D5:G5) -> 8
A6: 46287 | B6: Martes | C6: Hábil | D6: =SUMIFS('Bitácora diaria'!$G:$G,'Bitácora diaria'!$A:$A,$A6,'Bitácora diaria'!$F:$F,"Generación") -> 6 | E6: =SUMIFS('Bitácora diaria'!$G:$G,'Bitácora diaria'!$A:$A,$A6,'Bitácora diaria'!$F:$F,"Revisión") -> 0 | F6: =SUMIFS('Bitácora diaria'!$G:$G,'Bitácora diaria'!$A:$A,$A6,'Bitácora diaria'!$F:$F,"Control de calidad") -> 0 | G6: =SUMIFS('Bitácora diaria'!$G:$G,'Bitácora diaria'!$A:$A,$A6,'Bitácora diaria'!$F:$F,"Virtualización") -> 0 | I6: =SUM(D6:G6) -> 6
A7: 46288 | B7: Miércoles | C7: Hábil | D7: =SUMIFS('Bitácora diaria'!$G:$G,'Bitácora diaria'!$A:$A,$A7,'Bitácora diaria'!$F:$F,"Generación") -> 6 | E7: =SUMIFS('Bitácora diaria'!$G:$G,'Bitácora diaria'!$A:$A,$A7,'Bitácora diaria'!$F:$F,"Revisión") -> 0 | F7: =SUMIFS('Bitácora diaria'!$G:$G,'Bitácora diaria'!$A:$A,$A7,'Bitácora diaria'!$F:$F,"Control de calidad") -> 0 | G7: =SUMIFS('Bitácora diaria'!$G:$G,'Bitácora diaria'!$A:$A,$A7,'Bitácora diaria'!$F:$F,"Virtualización") -> 0 | I7: =SUM(D7:G7) -> 6
A8: 46289 | B8: Jueves | C8: Hábil | D8: =SUMIFS('Bitácora diaria'!$G:$G,'Bitácora diaria'!$A:$A,$A8,'Bitácora diaria'!$F:$F,"Generación") -> 6 | E8: =SUMIFS('Bitácora diaria'!$G:$G,'Bitácora diaria'!$A:$A,$A8,'Bitácora diaria'!$F:$F,"Revisión") -> 10 | F8: =SUMIFS('Bitácora diaria'!$G:$G,'Bitácora diaria'!$A:$A,$A8,'Bitácora diaria'!$F:$F,"Control de calidad") -> 0 | G8: =SUMIFS('Bitácora diaria'!$G:$G,'Bitácora diaria'!$A:$A,$A8,'Bitácora diaria'!$F:$F,"Virtualización") -> 0 | I8: =SUM(D8:G8) -> 16
A9: 46290 | B9: Viernes | C9: Hábil | D9: =SUMIFS('Bitácora diaria'!$G:$G,'Bitácora diaria'!$A:$A,$A9,'Bitácora diaria'!$F:$F,"Generación") -> 0 | E9: =SUMIFS('Bitácora diaria'!$G:$G,'Bitácora diaria'!$A:$A,$A9,'Bitácora diaria'!$F:$F,"Revisión") -> 8 | F9: =SUMIFS('Bitácora diaria'!$G:$G,'Bitácora diaria'!$A:$A,$A9,'Bitácora diaria'!$F:$F,"Control de calidad") -> 0 | G9: =SUMIFS('Bitácora diaria'!$G:$G,'Bitácora diaria'!$A:$A,$A9,'Bitácora diaria'!$F:$F,"Virtualización") -> 0 | I9: =SUM(D9:G9) -> 8
A10: 46293 | B10: Lunes | C10: Hábil | D10: =SUMIFS('Bitácora diaria'!$G:$G,'Bitácora diaria'!$A:$A,$A10,'Bitácora diaria'!$F:$F,"Generación") -> 0 | E10: =SUMIFS('Bitácora diaria'!$G:$G,'Bitácora diaria'!$A:$A,$A10,'Bitácora diaria'!$F:$F,"Revisión") -> 8 | F10: =SUMIFS('Bitácora diaria'!$G:$G,'Bitácora diaria'!$A:$A,$A10,'Bitácora diaria'!$F:$F,"Control de calidad") -> 0 | G10: =SUMIFS('Bitácora diaria'!$G:$G,'Bitácora diaria'!$A:$A,$A10,'Bitácora diaria'!$F:$F,"Virtualización") -> 0 | I10: =SUM(D10:G10) -> 8
A11: 46294 | B11: Martes | C11: Hábil | D11: =SUMIFS('Bitácora diaria'!$G:$G,'Bitácora diaria'!$A:$A,$A11,'Bitácora diaria'!$F:$F,"Generación") -> 0 | E11: =SUMIFS('Bitácora diaria'!$G:$G,'Bitácora diaria'!$A:$A,$A11,'Bitácora diaria'!$F:$F,"Revisión") -> 8 | F11: =SUMIFS('Bitácora diaria'!$G:$G,'Bitácora diaria'!$A:$A,$A11,'Bitácora diaria'!$F:$F,"Control de calidad") -> 0 | G11: =SUMIFS('Bitácora diaria'!$G:$G,'Bitácora diaria'!$A:$A,$A11,'Bitácora diaria'!$F:$F,"Virtualización") -> 0 | I11: =SUM(D11:G11) -> 8
A12: 46295 | B12: Miércoles | C12: Hábil | D12: =SUMIFS('Bitácora diaria'!$G:$G,'Bitácora diaria'!$A:$A,$A12,'Bitácora diaria'!$F:$F,"Generación") -> 0 | E12: =SUMIFS('Bitácora diaria'!$G:$G,'Bitácora diaria'!$A:$A,$A12,'Bitácora diaria'!$F:$F,"Revisión") -> 8 | F12: =SUMIFS('Bitácora diaria'!$G:$G,'Bitácora diaria'!$A:$A,$A12,'Bitácora diaria'!$F:$F,"Control de calidad") -> 0 | G12: =SUMIFS('Bitácora diaria'!$G:$G,'Bitácora diaria'!$A:$A,$A12,'Bitácora diaria'!$F:$F,"Virtualización") -> 0 | I12: =SUM(D12:G12) -> 8
A13: 46296 | B13: Jueves | C13: Hábil | D13: =SUMIFS('Bitácora diaria'!$G:$G,'Bitácora diaria'!$A:$A,$A13,'Bitácora diaria'!$F:$F,"Generación") -> 0 | E13: =SUMIFS('Bitácora diaria'!$G:$G,'Bitácora diaria'!$A:$A,$A13,'Bitácora diaria'!$F:$F,"Revisión") -> 8 | F13: =SUMIFS('Bitácora diaria'!$G:$G,'Bitácora diaria'!$A:$A,$A13,'Bitácora diaria'!$F:$F,"Control de calidad") -> 10 | G13: =SUMIFS('Bitácora diaria'!$G:$G,'Bitácora diaria'!$A:$A,$A13,'Bitácora diaria'!$F:$F,"Virtualización") -> 0 | I13: =SUM(D13:G13) -> 18
... A19: 46304 | B19: Viernes | C19: Hábil | D19: =SUMIFS('Bitácora diaria'!$G:$G,'Bitácora diaria'!$A:$A,$A19,'Bitácora diaria'!$F:$F,"Generación") -> 0 | E19: =SUMIFS('Bitácora diaria'!$G:$G,'Bitácora diaria'!$A:$A,$A19,'Bitácora diaria'!$F:$F,"Revisión") -> 0 | F19: =SUMIFS('Bitácora diaria'!$G:$G,'Bitácora diaria'!$A:$A,$A19,'Bitácora diaria'!$F:$F,"Control de calidad") -> 0 | G19: =SUMIFS('Bitácora diaria'!$G:$G,'Bitácora diaria'!$A:$A,$A19,'Bitácora diaria'!$F:$F,"Virtualización") -> 10 | I19: =SUM(D19:G19) -> 10
A20: 46307 | B20: Lunes | C20: Festivo | D20: =SUMIFS('Bitácora diaria'!$G:$G,'Bitácora diaria'!$A:$A,$A20,'Bitácora diaria'!$F:$F,"Generación") -> 0 | E20: =SUMIFS('Bitácora diaria'!$G:$G,'Bitácora diaria'!$A:$A,$A20,'Bitácora diaria'!$F:$F,"Revisión") -> 0 | F20: =SUMIFS('Bitácora diaria'!$G:$G,'Bitácora diaria'!$A:$A,$A20,'Bitácora diaria'!$F:$F,"Control de calidad") -> 0 | G20: =SUMIFS('Bitácora diaria'!$G:$G,'Bitácora diaria'!$A:$A,$A20,'Bitácora diaria'!$F:$F,"Virtualización") -> 0 | H20: Día de la Raza | I20: =SUM(D20:G20) -> 0
A21: 46308 | B21: Martes | C21: Hábil | D21: =SUMIFS('Bitácora diaria'!$G:$G,'Bitácora diaria'!$A:$A,$A21,'Bitácora diaria'!$F:$F,"Generación") -> 0 | E21: =SUMIFS('Bitácora diaria'!$G:$G,'Bitácora diaria'!$A:$A,$A21,'Bitácora diaria'!$F:$F,"Revisión") -> 0 | F21: =SUMIFS('Bitácora diaria'!$G:$G,'Bitácora diaria'!$A:$A,$A21,'Bitácora diaria'!$F:$F,"Control de calidad") -> 0 | G21: =SUMIFS('Bitácora diaria'!$G:$G,'Bitácora diaria'!$A:$A,$A21,'Bitácora diaria'!$F:$F,"Virtualización") -> 10 | I21: =SUM(D21:G21) -> 10
A22: 46309 | B22: Miércoles | C22: Hábil | D22: =SUMIFS('Bitácora diaria'!$G:$G,'Bitácora diaria'!$A:$A,$A22,'Bitácora diaria'!$F:$F,"Generación") -> 0 | E22: =SUMIFS('Bitácora diaria'!$G:$G,'Bitácora diaria'!$A:$A,$A22,'Bitácora diaria'!$F:$F,"Revisión") -> 0 | F22: =SUMIFS('Bitácora diaria'!$G:$G,'Bitácora diaria'!$A:$A,$A22,'Bitácora diaria'!$F:$F,"Control de calidad") -> 0 | G22: =SUMIFS('Bitácora diaria'!$G:$G,'Bitácora diaria'!$A:$A,$A22,'Bitácora diaria'!$F:$F,"Virtualización") -> 10 | I22: =SUM(D22:G22) -> 10
A23: 46310 | B23: Jueves | C23: Hábil | D23: =SUMIFS('Bitácora diaria'!$G:$G,'Bitácora diaria'!$A:$A,$A23,'Bitácora diaria'!$F:$F,"Generación") -> 0 | E23: =SUMIFS('Bitácora diaria'!$G:$G,'Bitácora diaria'!$A:$A,$A23,'Bitácora diaria'!$F:$F,"Revisión") -> 0 | F23: =SUMIFS('Bitácora diaria'!$G:$G,'Bitácora diaria'!$A:$A,$A23,'Bitácora diaria'!$F:$F,"Control de calidad") -> 0 | G23: =SUMIFS('Bitácora diaria'!$G:$G,'Bitácora diaria'!$A:$A,$A23,'Bitácora diaria'!$F:$F,"Virtualización") -> 10 | I23: =SUM(D23:G23) -> 10
A24: 46311 | B24: Viernes | C24: Hábil | D24: =SUMIFS('Bitácora diaria'!$G:$G,'Bitácora diaria'!$A:$A,$A24,'Bitácora diaria'!$F:$F,"Generación") -> 14 | E24: =SUMIFS('Bitácora diaria'!$G:$G,'Bitácora diaria'!$A:$A,$A24,'Bitácora diaria'!$F:$F,"Revisión") -> 0 | F24: =SUMIFS('Bitácora diaria'!$G:$G,'Bitácora diaria'!$A:$A,$A24,'Bitácora diaria'!$F:$F,"Control de calidad") -> 0 | G24: =SUMIFS('Bitácora diaria'!$G:$G,'Bitácora diaria'!$A:$A,$A24,'Bitácora diaria'!$F:$F,"Virtualización") -> 0 | I24: =SUM(D24:G24) -> 14
A25: 46314 | B25: Lunes | C25: Hábil | D25: =SUMIFS('Bitácora diaria'!$G:$G,'Bitácora diaria'!$A:$A,$A25,'Bitácora diaria'!$F:$F,"Generación") -> 12 | E25: =SUMIFS('Bitácora diaria'!$G:$G,'Bitácora diaria'!$A:$A,$A25,'Bitácora diaria'!$F:$F,"Revisión") -> 0 | F25: =SUMIFS('Bitácora diaria'!$G:$G,'Bitácora diaria'!$A:$A,$A25,'Bitácora diaria'!$F:$F,"Control de calidad") -> 0 | G25: =SUMIFS('Bitácora diaria'!$G:$G,'Bitácora diaria'!$A:$A,$A25,'Bitácora diaria'!$F:$F,"Virtualización") -> 0 | I25: =SUM(D25:G25) -> 12
A26: 46315 | B26: Martes | C26: Hábil | D26: =SUMIFS('Bitácora diaria'!$G:$G,'Bitácora diaria'!$A:$A,$A26,'Bitácora diaria'!$F:$F,"Generación") -> 12 | E26: =SUMIFS('Bitácora diaria'!$G:$G,'Bitácora diaria'!$A:$A,$A26,'Bitácora diaria'!$F:$F,"Revisión") -> 0 | F26: =SUMIFS('Bitácora diaria'!$G:$G,'Bitácora diaria'!$A:$A,$A26,'Bitácora diaria'!$F:$F,"Control de calidad") -> 0 | G26: =SUMIFS('Bitácora diaria'!$G:$G,'Bitácora diaria'!$A:$A,$A26,'Bitácora diaria'!$F:$F,"Virtualización") -> 0 | I26: =SUM(D26:G26) -> 12
A27: 46316 | B27: Miércoles | C27: Hábil | D27: =SUMIFS('Bitácora diaria'!$G:$G,'Bitácora diaria'!$A:$A,$A27,'Bitácora diaria'!$F:$F,"Generación") -> 12 | E27: =SUMIFS('Bitácora diaria'!$G:$G,'Bitácora diaria'!$A:$A,$A27,'Bitácora diaria'!$F:$F,"Revisión") -> 14 | F27: =SUMIFS('Bitácora diaria'!$G:$G,'Bitácora diaria'!$A:$A,$A27,'Bitácora diaria'!$F:$F,"Control de calidad") -> 0 | G27: =SUMIFS('Bitácora diaria'!$G:$G,'Bitácora diaria'!$A:$A,$A27,'Bitácora diaria'!$F:$F,"Virtualización") -> 0 | I27: =SUM(D27:G27) -> 26
A28: 46317 | B28: Jueves | C28: Hábil | D28: =SUMIFS('Bitácora diaria'!$G:$G,'Bitácora diaria'!$A:$A,$A28,'Bitácora diaria'!$F:$F,"Generación") -> 0 | E28: =SUMIFS('Bitácora diaria'!$G:$G,'Bitácora diaria'!$A:$A,$A28,'Bitácora diaria'!$F:$F,"Revisión") -> 12 | F28: =SUMIFS('Bitácora diaria'!$G:$G,'Bitácora diaria'!$A:$A,$A28,'Bitácora diaria'!$F:$F,"Control de calidad") -> 0 | G28: =SUMIFS('Bitácora diaria'!$G:$G,'Bitácora diaria'!$A:$A,$A28,'Bitácora diaria'!$F:$F,"Virtualización") -> 0 | I28: =SUM(D28:G28) -> 12
A29: 46318 | B29: Viernes | C29: Hábil | D29: =SUMIFS('Bitácora diaria'!$G:$G,'Bitácora diaria'!$A:$A,$A29,'Bitácora diaria'!$F:$F,"Generación") -> 0 | E29: =SUMIFS('Bitácora diaria'!$G:$G,'Bitácora diaria'!$A:$A,$A29,'Bitácora diaria'!$F:$F,"Revisión") -> 12 | F29: =SUMIFS('Bitácora diaria'!$G:$G,'Bitácora diaria'!$A:$A,$A29,'Bitácora diaria'!$F:$F,"Control de calidad") -> 0 | G29: =SUMIFS('Bitácora diaria'!$G:$G,'Bitácora diaria'!$A:$A,$A29,'Bitácora diaria'!$F:$F,"Virtualización") -> 0 | I29: =SUM(D29:G29) -> 12
A30: 46321 | B30: Lunes | C30: Hábil | D30: =SUMIFS('Bitácora diaria'!$G:$G,'Bitácora diaria'!$A:$A,$A30,'Bitácora diaria'!$F:$F,"Generación") -> 0 | E30: =SUMIFS('Bitácora diaria'!$G:$G,'Bitácora diaria'!$A:$A,$A30,'Bitácora diaria'!$F:$F,"Revisión") -> 12 | F30: =SUMIFS('Bitácora diaria'!$G:$G,'Bitácora diaria'!$A:$A,$A30,'Bitácora diaria'!$F:$F,"Control de calidad") -> 18 | G30: =SUMIFS('Bitácora diaria'!$G:$G,'Bitácora diaria'!$A:$A,$A30,'Bitácora diaria'!$F:$F,"Virtualización") -> 0 | I30: =SUM(D30:G30) -> 30
A31: 46322 | B31: Martes | C31: Hábil | D31: =SUMIFS('Bitácora diaria'!$G:$G,'Bitácora diaria'!$A:$A,$A31,'Bitácora diaria'!$F:$F,"Generación") -> 0 | E31: =SUMIFS('Bitácora diaria'!$G:$G,'Bitácora diaria'!$A:$A,$A31,'Bitácora diaria'!$F:$F,"Revisión") -> 0 | F31: =SUMIFS('Bitácora diaria'!$G:$G,'Bitácora diaria'!$A:$A,$A31,'Bitácora diaria'!$F:$F,"Control de calidad") -> 16 | G31: =SUMIFS('Bitácora diaria'!$G:$G,'Bitácora diaria'!$A:$A,$A31,'Bitácora diaria'!$F:$F,"Virtualización") -> 0 | I31: =SUM(D31:G31) -> 16
A32: 46323 | B32: Miércoles | C32: Hábil | D32: =SUMIFS('Bitácora diaria'!$G:$G,'Bitácora diaria'!$A:$A,$A32,'Bitácora diaria'!$F:$F,"Generación") -> 0 | E32: =SUMIFS('Bitácora diaria'!$G:$G,'Bitácora diaria'!$A:$A,$A32,'Bitácora diaria'!$F:$F,"Revisión") -> 0 | F32: =SUMIFS('Bitácora diaria'!$G:$G,'Bitácora diaria'!$A:$A,$A32,'Bitácora diaria'!$F:$F,"Control de calidad") -> 16 | G32: =SUMIFS('Bitácora diaria'!$G:$G,'Bitácora diaria'!$A:$A,$A32,'Bitácora diaria'!$F:$F,"Virtualización") -> 18 | I32: =SUM(D32:G32) -> 34
... A34: 46325 | B34: Viernes | C34: Hábil | D34: =SUMIFS('Bitácora diaria'!$G:$G,'Bitácora diaria'!$A:$A,$A34,'Bitácora diaria'!$F:$F,"Generación") -> 0 | E34: =SUMIFS('Bitácora diaria'!$G:$G,'Bitácora diaria'!$A:$A,$A34,'Bitácora diaria'!$F:$F,"Revisión") -> 0 | F34: =SUMIFS('Bitácora diaria'!$G:$G,'Bitácora diaria'!$A:$A,$A34,'Bitácora diaria'!$F:$F,"Control de calidad") -> 0 | G34: =SUMIFS('Bitácora diaria'!$G:$G,'Bitácora diaria'!$A:$A,$A34,'Bitácora diaria'!$F:$F,"Virtualización") -> 16 | I34: =SUM(D34:G34) -> 16
A35: 46328 | B35: Lunes | C35: Festivo | D35: =SUMIFS('Bitácora diaria'!$G:$G,'Bitácora diaria'!$A:$A,$A35,'Bitácora diaria'!$F:$F,"Generación") -> 0 | E35: =SUMIFS('Bitácora diaria'!$G:$G,'Bitácora diaria'!$A:$A,$A35,'Bitácora diaria'!$F:$F,"Revisión") -> 0 | F35: =SUMIFS('Bitácora diaria'!$G:$G,'Bitácora diaria'!$A:$A,$A35,'Bitácora diaria'!$F:$F,"Control de calidad") -> 0 | G35: =SUMIFS('Bitácora diaria'!$G:$G,'Bitácora diaria'!$A:$A,$A35,'Bitácora diaria'!$F:$F,"Virtualización") -> 0 | H35: Todos los Santos | I35: =SUM(D35:G35) -> 0
A36: 46329 | B36: Martes | C36: Hábil | D36: =SUMIFS('Bitácora diaria'!$G:$G,'Bitácora diaria'!$A:$A,$A36,'Bitácora diaria'!$F:$F,"Generación") -> 18 | E36: =SUMIFS('Bitácora diaria'!$G:$G,'Bitácora diaria'!$A:$A,$A36,'Bitácora diaria'!$F:$F,"Revisión") -> 0 | F36: =SUMIFS('Bitácora diaria'!$G:$G,'Bitácora diaria'!$A:$A,$A36,'Bitácora diaria'!$F:$F,"Control de calidad") -> 0 | G36: =SUMIFS('Bitácora diaria'!$G:$G,'Bitácora diaria'!$A:$A,$A36,'Bitácora diaria'!$F:$F,"Virtualización") -> 0 | I36: =SUM(D36:G36) -> 18
A37: 46330 | B37: Miércoles | C37: Hábil | D37: =SUMIFS('Bitácora diaria'!$G:$G,'Bitácora diaria'!$A:$A,$A37,'Bitácora diaria'!$F:$F,"Generación") -> 16 | E37: =SUMIFS('Bitácora diaria'!$G:$G,'Bitácora diaria'!$A:$A,$A37,'Bitácora diaria'!$F:$F,"Revisión") -> 0 | F37: =SUMIFS('Bitácora diaria'!$G:$G,'Bitácora diaria'!$A:$A,$A37,'Bitácora diaria'!$F:$F,"Control de calidad") -> 0 | G37: =SUMIFS('Bitácora diaria'!$G:$G,'Bitácora diaria'!$A:$A,$A37,'Bitácora diaria'!$F:$F,"Virtualización") -> 0 | I37: =SUM(D37:G37) -> 16
A38: 46331 | B38: Jueves | C38: Hábil | D38: =SUMIFS('Bitácora diaria'!$G:$G,'Bitácora diaria'!$A:$A,$A38,'Bitácora diaria'!$F:$F,"Generación") -> 16 | E38: =SUMIFS('Bitácora diaria'!$G:$G,'Bitácora diaria'!$A:$A,$A38,'Bitácora diaria'!$F:$F,"Revisión") -> 18 | F38: =SUMIFS('Bitácora diaria'!$G:$G,'Bitácora diaria'!$A:$A,$A38,'Bitácora diaria'!$F:$F,"Control de calidad") -> 0 | G38: =SUMIFS('Bitácora diaria'!$G:$G,'Bitácora diaria'!$A:$A,$A38,'Bitácora diaria'!$F:$F,"Virtualización") -> 0 | I38: =SUM(D38:G38) -> 34
A39: 46332 | B39: Viernes | C39: Hábil | D39: =SUMIFS('Bitácora diaria'!$G:$G,'Bitácora diaria'!$A:$A,$A39,'Bitácora diaria'!$F:$F,"Generación") -> 0 | E39: =SUMIFS('Bitácora diaria'!$G:$G,'Bitácora diaria'!$A:$A,$A39,'Bitácora diaria'!$F:$F,"Revisión") -> 16 | F39: =SUMIFS('Bitácora diaria'!$G:$G,'Bitácora diaria'!$A:$A,$A39,'Bitácora diaria'!$F:$F,"Control de calidad") -> 0 | G39: =SUMIFS('Bitácora diaria'!$G:$G,'Bitácora diaria'!$A:$A,$A39,'Bitácora diaria'!$F:$F,"Virtualización") -> 0 | I39: =SUM(D39:G39) -> 16
A40: 46335 | B40: Lunes | C40: Hábil | D40: =SUMIFS('Bitácora diaria'!$G:$G,'Bitácora diaria'!$A:$A,$A40,'Bitácora diaria'!$F:$F,"Generación") -> 0 | E40: =SUMIFS('Bitácora diaria'!$G:$G,'Bitácora diaria'!$A:$A,$A40,'Bitácora diaria'!$F:$F,"Revisión") -> 16 | F40: =SUMIFS('Bitácora diaria'!$G:$G,'Bitácora diaria'!$A:$A,$A40,'Bitácora diaria'!$F:$F,"Control de calidad") -> 18 | G40: =SUMIFS('Bitácora diaria'!$G:$G,'Bitácora diaria'!$A:$A,$A40,'Bitácora diaria'!$F:$F,"Virtualización") -> 0 | I40: =SUM(D40:G40) -> 34
A41: 46336 | B41: Martes | C41: Hábil | D41: =SUMIFS('Bitácora diaria'!$G:$G,'Bitácora diaria'!$A:$A,$A41,'Bitácora diaria'!$F:$F,"Generación") -> 0 | E41: =SUMIFS('Bitácora diaria'!$G:$G,'Bitácora diaria'!$A:$A,$A41,'Bitácora diaria'!$F:$F,"Revisión") -> 0 | F41: =SUMIFS('Bitácora diaria'!$G:$G,'Bitácora diaria'!$A:$A,$A41,'Bitácora diaria'!$F:$F,"Control de calidad") -> 16 | G41: =SUMIFS('Bitácora diaria'!$G:$G,'Bitácora diaria'!$A:$A,$A41,'Bitácora diaria'!$F:$F,"Virtualización") -> 0 | I41: =SUM(D41:G41) -> 16
A42: 46337 | B42: Miércoles | C42: Hábil | D42: =SUMIFS('Bitácora diaria'!$G:$G,'Bitácora diaria'!$A:$A,$A42,'Bitácora diaria'!$F:$F,"Generación") -> 0 | E42: =SUMIFS('Bitácora diaria'!$G:$G,'Bitácora diaria'!$A:$A,$A42,'Bitácora diaria'!$F:$F,"Revisión") -> 0 | F42: =SUMIFS('Bitácora diaria'!$G:$G,'Bitácora diaria'!$A:$A,$A42,'Bitácora diaria'!$F:$F,"Control de calidad") -> 16 | G42: =SUMIFS('Bitácora diaria'!$G:$G,'Bitácora diaria'!$A:$A,$A42,'Bitácora diaria'!$F:$F,"Virtualización") -> 18 | I42: =SUM(D42:G42) -> 34
A43: 46338 | B43: Jueves | C43: Hábil | D43: =SUMIFS('Bitácora diaria'!$G:$G,'Bitácora diaria'!$A:$A,$A43,'Bitácora diaria'!$F:$F,"Generación") -> 0 | E43: =SUMIFS('Bitácora diaria'!$G:$G,'Bitácora diaria'!$A:$A,$A43,'Bitácora diaria'!$F:$F,"Revisión") -> 0 | F43: =SUMIFS('Bitácora diaria'!$G:$G,'Bitácora diaria'!$A:$A,$A43,'Bitácora diaria'!$F:$F,"Control de calidad") -> 0 | G43: =SUMIFS('Bitácora diaria'!$G:$G,'Bitácora diaria'!$A:$A,$A43,'Bitácora diaria'!$F:$F,"Virtualización") -> 16 | I43: =SUM(D43:G43) -> 16
A44: 46339 | B44: Viernes | C44: Hábil | D44: =SUMIFS('Bitácora diaria'!$G:$G,'Bitácora diaria'!$A:$A,$A44,'Bitácora diaria'!$F:$F,"Generación") -> 0 | E44: =SUMIFS('Bitácora diaria'!$G:$G,'Bitácora diaria'!$A:$A,$A44,'Bitácora diaria'!$F:$F,"Revisión") -> 0 | F44: =SUMIFS('Bitácora diaria'!$G:$G,'Bitácora diaria'!$A:$A,$A44,'Bitácora diaria'!$F:$F,"Control de calidad") -> 0 | G44: =SUMIFS('Bitácora diaria'!$G:$G,'Bitácora diaria'!$A:$A,$A44,'Bitácora diaria'!$F:$F,"Virtualización") -> 16 | I44: =SUM(D44:G44) -> 16
A45: 46342 | B45: Lunes | C45: Festivo | D45: =SUMIFS('Bitácora diaria'!$G:$G,'Bitácora diaria'!$A:$A,$A45,'Bitácora diaria'!$F:$F,"Generación") -> 0 | E45: =SUMIFS('Bitácora diaria'!$G:$G,'Bitácora diaria'!$A:$A,$A45,'Bitácora diaria'!$F:$F,"Revisión") -> 0 | F45: =SUMIFS('Bitácora diaria'!$G:$G,'Bitácora diaria'!$A:$A,$A45,'Bitácora diaria'!$F:$F,"Control de calidad") -> 0 | G45: =SUMIFS('Bitácora diaria'!$G:$G,'Bitácora diaria'!$A:$A,$A45,'Bitácora diaria'!$F:$F,"Virtualización") -> 0 | H45: Independencia de Cartagena | I45: =SUM(D45:G45) -> 0
A46: 46343 | B46: Martes | C46: Hábil | D46: =SUMIFS('Bitácora diaria'!$G:$G,'Bitácora diaria'!$A:$A,$A46,'Bitácora diaria'!$F:$F,"Generación") -> 14 | E46: =SUMIFS('Bitácora diaria'!$G:$G,'Bitácora diaria'!$A:$A,$A46,'Bitácora diaria'!$F:$F,"Revisión") -> 0 | F46: =SUMIFS('Bitácora diaria'!$G:$G,'Bitácora diaria'!$A:$A,$A46,'Bitácora diaria'!$F:$F,"Control de calidad") -> 0 | G46: =SUMIFS('Bitácora diaria'!$G:$G,'Bitácora diaria'!$A:$A,$A46,'Bitácora diaria'!$F:$F,"Virtualización") -> 0 | I46: =SUM(D46:G46) -> 14
...

Sheet Curva de avance
A1: Curva de avance — PAD virtualizados acumulados
A3: Fecha | B3: Plan del día | C3: Plan acumulado | D3: Real acumulado
A4: 46281 | B4: =SUMIFS('Bitácora diaria'!$G:$G,'Bitácora diaria'!$A:$A,$A4,'Bitácora diaria'!$F:$F,"Virtualización") -> 0 | C4: =SUM($B$4:B4) -> 0 | D4: =IF(SUMIFS('Bitácora diaria'!$H:$H,'Bitácora diaria'!$A:$A,"<="&$A4,'Bitácora diaria'!$F:$F,"Virtualización")=0,"",SUMIFS('Bitácora diaria'!$H:$H,'Bitácora diaria'!$A:$A,"<="&$A4,'Bitácora diaria'!$F:$F,"Virtualización"))
A5: 46282 | B5: =SUMIFS('Bitácora diaria'!$G:$G,'Bitácora diaria'!$A:$A,$A5,'Bitácora diaria'!$F:$F,"Virtualización") -> 0 | C5: =SUM($B$4:B5) -> 0 | D5: =IF(SUMIFS('Bitácora diaria'!$H:$H,'Bitácora diaria'!$A:$A,"<="&$A5,'Bitácora diaria'!$F:$F,"Virtualización")=0,"",SUMIFS('Bitácora diaria'!$H:$H,'Bitácora diaria'!$A:$A,"<="&$A5,'Bitácora diaria'!$F:$F,"Virtualización"))
A6: 46283 | B6: =SUMIFS('Bitácora diaria'!$G:$G,'Bitácora diaria'!$A:$A,$A6,'Bitácora diaria'!$F:$F,"Virtualización") -> 0 | C6: =SUM($B$4:B6) -> 0 | D6: =IF(SUMIFS('Bitácora diaria'!$H:$H,'Bitácora diaria'!$A:$A,"<="&$A6,'Bitácora diaria'!$F:$F,"Virtualización")=0,"",SUMIFS('Bitácora diaria'!$H:$H,'Bitácora diaria'!$A:$A,"<="&$A6,'Bitácora diaria'!$F:$F,"Virtualización"))
A7: 46286 | B7: =SUMIFS('Bitácora diaria'!$G:$G,'Bitácora diaria'!$A:$A,$A7,'Bitácora diaria'!$F:$F,"Virtualización") -> 0 | C7: =SUM($B$4:B7) -> 0 | D7: =IF(SUMIFS('Bitácora diaria'!$H:$H,'Bitácora diaria'!$A:$A,"<="&$A7,'Bitácora diaria'!$F:$F,"Virtualización")=0,"",SUMIFS('Bitácora diaria'!$H:$H,'Bitácora diaria'!$A:$A,"<="&$A7,'Bitácora diaria'!$F:$F,"Virtualización"))
A8: 46287 | B8: =SUMIFS('Bitácora diaria'!$G:$G,'Bitácora diaria'!$A:$A,$A8,'Bitácora diaria'!$F:$F,"Virtualización") -> 0 | C8: =SUM($B$4:B8) -> 0 | D8: =IF(SUMIFS('Bitácora diaria'!$H:$H,'Bitácora diaria'!$A:$A,"<="&$A8,'Bitácora diaria'!$F:$F,"Virtualización")=0,"",SUMIFS('Bitácora diaria'!$H:$H,'Bitácora diaria'!$A:$A,"<="&$A8,'Bitácora diaria'!$F:$F,"Virtualización"))
A9: 46288 | B9: =SUMIFS('Bitácora diaria'!$G:$G,'Bitácora diaria'!$A:$A,$A9,'Bitácora diaria'!$F:$F,"Virtualización") -> 0 | C9: =SUM($B$4:B9) -> 0 | D9: =IF(SUMIFS('Bitácora diaria'!$H:$H,'Bitácora diaria'!$A:$A,"<="&$A9,'Bitácora diaria'!$F:$F,"Virtualización")=0,"",SUMIFS('Bitácora diaria'!$H:$H,'Bitácora diaria'!$A:$A,"<="&$A9,'Bitácora diaria'!$F:$F,"Virtualización"))
A10: 46289 | B10: =SUMIFS('Bitácora diaria'!$G:$G,'Bitácora diaria'!$A:$A,$A10,'Bitácora diaria'!$F:$F,"Virtualización") -> 0 | C10: =SUM($B$4:B10) -> 0 | D10: =IF(SUMIFS('Bitácora diaria'!$H:$H,'Bitácora diaria'!$A:$A,"<="&$A10,'Bitácora diaria'!$F:$F,"Virtualización")=0,"",SUMIFS('Bitácora diaria'!$H:$H,'Bitácora diaria'!$A:$A,"<="&$A10,'Bitácora diaria'!$F:$F,"Virtualización"))
A11: 46290 | B11: =SUMIFS('Bitácora diaria'!$G:$G,'Bitácora diaria'!$A:$A,$A11,'Bitácora diaria'!$F:$F,"Virtualización") -> 0 | C11: =SUM($B$4:B11) -> 0 | D11: =IF(SUMIFS('Bitácora diaria'!$H:$H,'Bitácora diaria'!$A:$A,"<="&$A11,'Bitácora diaria'!$F:$F,"Virtualización")=0,"",SUMIFS('Bitácora diaria'!$H:$H,'Bitácora diaria'!$A:$A,"<="&$A11,'Bitácora diaria'!$F:$F,"Virtualización"))
A12: 46293 | B12: =SUMIFS('Bitácora diaria'!$G:$G,'Bitácora diaria'!$A:$A,$A12,'Bitácora diaria'!$F:$F,"Virtualización") -> 0 | C12: =SUM($B$4:B12) -> 0 | D12: =IF(SUMIFS('Bitácora diaria'!$H:$H,'Bitácora diaria'!$A:$A,"<="&$A12,'Bitácora diaria'!$F:$F,"Virtualización")=0,"",SUMIFS('Bitácora diaria'!$H:$H,'Bitácora diaria'!$A:$A,"<="&$A12,'Bitácora diaria'!$F:$F,"Virtualización"))
A13: 46294 | B13: =SUMIFS('Bitácora diaria'!$G:$G,'Bitácora diaria'!$A:$A,$A13,'Bitácora diaria'!$F:$F,"Virtualización") -> 0 | C13: =SUM($B$4:B13) -> 0 | D13: =IF(SUMIFS('Bitácora diaria'!$H:$H,'Bitácora diaria'!$A:$A,"<="&$A13,'Bitácora diaria'!$F:$F,"Virtualización")=0,"",SUMIFS('Bitácora diaria'!$H:$H,'Bitácora diaria'!$A:$A,"<="&$A13,'Bitácora diaria'!$F:$F,"Virtualización"))
A14: 46295 | B14: =SUMIFS('Bitácora diaria'!$G:$G,'Bitácora diaria'!$A:$A,$A14,'Bitácora diaria'!$F:$F,"Virtualización") -> 0 | C14: =SUM($B$4:B14) -> 0 | D14: =IF(SUMIFS('Bitácora diaria'!$H:$H,'Bitácora diaria'!$A:$A,"<="&$A14,'Bitácora diaria'!$F:$F,"Virtualización")=0,"",SUMIFS('Bitácora diaria'!$H:$H,'Bitácora diaria'!$A:$A,"<="&$A14,'Bitácora diaria'!$F:$F,"Virtualización"))
A15: 46296 | B15: =SUMIFS('Bitácora diaria'!$G:$G,'Bitácora diaria'!$A:$A,$A15,'Bitácora diaria'!$F:$F,"Virtualización") -> 0 | C15: =SUM($B$4:B15) -> 0 | D15: =IF(SUMIFS('Bitácora diaria'!$H:$H,'Bitácora diaria'!$A:$A,"<="&$A15,'Bitácora diaria'!$F:$F,"Virtualización")=0,"",SUMIFS('Bitácora diaria'!$H:$H,'Bitácora diaria'!$A:$A,"<="&$A15,'Bitácora diaria'!$F:$F,"Virtualización"))
... A54: 46356 | B54: =SUMIFS('Bitácora diaria'!$G:$G,'Bitácora diaria'!$A:$A,$A54,'Bitácora diaria'!$F:$F,"Virtualización") -> 16 | C54: =SUM($B$4:B54) -> 200 | D54: =IF(SUMIFS('Bitácora diaria'!$H:$H,'Bitácora diaria'!$A:$A,"<="&$A54,'Bitácora diaria'!$F:$F,"Virtualización")=0,"",SUMIFS('Bitácora diaria'!$H:$H,'Bitácora diaria'!$A:$A,"<="&$A54,'Bitácora diaria'!$F:$F,"Virtualización"))

Sheet Control
B1: Juan Manuel | C1: Juan Pablo | D1: Fecha De Carga | E1: Revisado Por Experto | F1: Cambios A Realizar | G1: Aprobado en segunda instancia | H1: Virtualizacion
A2: Total Pads Generados | B2: =COUNTA(B4:C38,B40:C82,B84:C94,B96:C141,B143:C149) -> 112 | E2: =COUNTA(E4:E30,E40:E68,E84:E90) -> 47 | F2: =COUNTA(F4:F30,F40:F68,F84:F90)-G2 -> 44 | G2: =COUNTA(G4:G30,G40:G68,G84:G90) -> 3 | H2: =COUNTA(H4:H30,H40:H68,H84:H90) -> 0
A3: FACULTAD CIENCIAS CONTABLES Y ECONOMICAS
A4: ESPECIALIZACIÓN EN GERENCIA PARA LA TRANFORMACIÓN DIGITAL | C4: Pensamiento Estratégico | D4: 46213 | E4: Si | F4: Cambios | G4: Si
A5: ESPECIALIZACIÓN EN GERENCIA PARA LA TRANFORMACIÓN DIGITAL | C5: Gestión del cambio y cultura digital | D5: 46063 | E5: Si | F5: Aprobado
A6: ESPECIALIZACIÓN EN GERENCIA PARA LA TRANFORMACIÓN DIGITAL | B6: Gestión de tecnologías de información y comunicación TIC | D6: 46063
A7: ESPECIALIZACIÓN EN GERENCIA PARA LA TRANFORMACIÓN DIGITAL | B7: Diseño de productos servicios y modelos de negocio | D7: 46063
A8: ESPECIALIZACIÓN EN GERENCIA PARA LA TRANFORMACIÓN DIGITAL | C8: Plan de Marketing Digital | D8: 46063 | E8: Si | F8: Agregar Bibliografias
A9: ESPECIALIZACIÓN EN GERENCIA PARA LA TRANFORMACIÓN DIGITAL | B9: Analítica de negocios | D9: 46063 | E9: Si | F9: Agregar Bibliografias | G9: Si
A10: ESPECIALIZACIÓN EN GERENCIA PARA LA TRANFORMACIÓN DIGITAL | C10: Plan para la transformación digital | D10: 46063
A11: ESPECIALIZACIÓN EN GESTIÓN PÚBLICA | B11: Economía de lo Público | D11: 46063 | E11: Si | F11: Agregar Bibliografias
A12: ESPECIALIZACIÓN EN GESTIÓN PÚBLICA | C12: Modelo Integral de Planeación y Gestión (MIPG) | D12: 46063 | E12: Si | F12: Cambios
A13: ESPECIALIZACIÓN EN GESTIÓN PÚBLICA | B13: Estructura del Estado Colombiano y Gobernanza de las Políticas Públicas | D13: 46063
A14: ESPECIALIZACIÓN EN GESTIÓN PÚBLICA | C14: Presupuesto y Finanzas Públicas | D14: 46063
A15: ESPECIALIZACIÓN EN GESTIÓN PÚBLICA | B15: Análisis y gestión de las organizaciones públicas | D15: 46063
A16: ESPECIALIZACIÓN EN GESTIÓN PÚBLICA | C16: Contratación Estatal | D16: 46063 | E16: SI | F16: Agregar Bibliografias
A17: ESPECIALIZACIÓN EN GESTIÓN PÚBLICA | B17: Desarrollo y Gestión Territorial | D17: 46063 | E17: Si | F17: Cambios
A18: ESPECIALIZACIÓN MARKETING DIGITAL | C18: Redes sociales en el marketing digital | D18: 46063 | E18: Si | F18: Cambios
A19: ESPECIALIZACIÓN MARKETING DIGITAL | B19: Psicología del consumidor digital | D19: 46063 | E19: Si | F19: Agregar Bibliografias
A20: ESPECIALIZACIÓN MARKETING DIGITAL | C20: Investigación de mercados digital | D20: 46063 | E20: Si | F20: Cambios
A21: ESPECIALIZACIÓN MARKETING DIGITAL | B21: Marketing de contenidos | D21: 46063 | E21: Si | F21: Cambios
A22: ESPECIALIZACIÓN MARKETING DIGITAL | C22: Comercio y venta de productos y servicios online | D22: 46063 | E22: Si | F22: Aprobado
A23: ESPECIALIZACIÓN MARKETING DIGITAL | B23: Analítica digital | D23: 46063 | E23: Si | F23: Aprobado
A24: ESPECIALIZACIÓN MARKETING DIGITAL | C24: Plan de marketing estratégico digital | D24: 46063 | E24: Si | F24: Cambios
A25: ESPECIALIZACIÓN EN GERENCIA FINANCIERA Y CONTABLE | B25: Legislación Financiera | D25: 46063
A26: ESPECIALIZACIÓN EN GERENCIA FINANCIERA Y CONTABLE | C26: Contabilidad Avanzada | D26: 46063 | E26: Si | F26: Agregar Bibliografias
A27: ESPECIALIZACIÓN EN GERENCIA FINANCIERA Y CONTABLE | B27: Diagnóstico estratégico y Financiero | D27: 46063 | E27: Si | F27: Agregar Bibliografias
A28: ESPECIALIZACIÓN EN GERENCIA FINANCIERA Y CONTABLE | C28: Análisis y Administración Financiera | D28: 46213
A29: ESPECIALIZACIÓN EN GERENCIA FINANCIERA Y CONTABLE | B29: Contexto Financiero Internacional | D29: 46063
A30: ESPECIALIZACIÓN EN GERENCIA FINANCIERA Y CONTABLE | C30: Econometría y herramentas Herramientas | D30: 46063 | E30: Si | F30: Agregar Bibliografias
A31: ADMINISTRACION DE EMPRESAS
A32: ADMINISTRACION DE EMPRESAS
A33: ADMINISTRACION DE EMPRESAS
A34: ADMINISTRACION DE EMPRESAS
A35: CONTADURIA PUBLICA
A36: CONTADURIA PUBLICA
A37: CONTADURIA PUBLICA
A38: CONTADURIA PUBLICA
A39: FACULTAD CIENCIAS AGROPECUARIAS
A40: ESPECIALIZACIÓN EN AGROECOLOGIA Y DESARROLLO AGROTURÍSTICO | B40: Economía rural y política pública | D40: 46152 | E40: Si | F40: Agregar Bibliografias
...
